Workbook
Name Slicer_ticker: #N/A
Name Slicer_ticker1: #N/A

Sheet Overview
A1: end_price | B1: max_price | C1: min_price | D1: total_return_pct
A2: 250.6 | B2: 257.38 | C2: 54.16 | D2: 246.47
A3: 420.76 | B3: 461.32 | C3: 128.64 | D3: 176.52
A4: 230.28 | B4: 235.83 | C4: 76.7 | D4: 111.44
A5: 417.41 | B5: 479.86 | C5: 24.08 | D5: 1355.4

Sheet RawData
A1: date | B1: open_price | C1: high | D1: low | E1: close | F1: volume | G1: ticker
A2: 43832 | B2: 71.344047 | C2: 72.394078 | D2: 71.091176 | E2: 72.33387 | F2: 135480400 | G2: AAPL
A3: 43833 | B3: 71.563228 | C3: 72.38928 | D3: 71.406689 | E3: 71.630661 | F3: 146322800 | G3: AAPL
A4: 43836 | B4: 70.754036 | C4: 72.239965 | D4: 70.503569 | E4: 72.201431 | F4: 118387200 | G4: AAPL
A5: 43837 | B5: 72.211049 | C5: 72.46633 | D5: 71.642689 | E5: 71.861847 | F5: 108872000 | G5: AAPL
A6: 43838 | B6: 71.565621 | C6: 73.318877 | D6: 71.565621 | E6: 73.017838 | F6: 132079200 | G6: AAPL
A7: 43839 | B7: 73.993202 | C7: 74.761457 | D7: 73.742742 | E7: 74.568794 | F7: 170108400 | G7: AAPL
A8: 43840 | B8: 74.802418 | C8: 75.300942 | D8: 74.236461 | E8: 74.737389 | F8: 140644800 | G8: AAPL
A9: 43843 | B9: 75.052871 | C9: 76.360587 | D9: 74.934858 | E9: 76.334091 | F9: 121532000 | G9: AAPL
A10: 43844 | B10: 76.271502 | C10: 76.481024 | D10: 75.180533 | E10: 75.303352 | F10: 161954400 | G10: AAPL
A11: 43845 | B11: 75.103456 | C11: 75.982491 | D11: 74.549538 | E11: 74.980629 | F11: 121923600 | G11: AAPL
A12: 43846 | B12: 75.522474 | C12: 76.030634 | D12: 75.161227 | E12: 75.919846 | F12: 108829200 | G12: AAPL
A13: 43847 | B13: 76.167901 | C13: 76.762756 | D13: 75.862047 | E13: 76.760353 | F13: 137816400 | G13: AAPL
... A5047: 45656 | B5047: 232.4677 | C5047: 232.4677 | D5047: 229.73909 | E5047: 230.27507 | F5047: 723232 | G5047: SAP.DE

Sheet Metrics
A1: date | B1: ticker | C1: MA_7 | D1: MA_30 | E1: MA_90 | F1: return | G1: volatility
A2: 43839 | B2: AAPL | C2: 72.602407 | D2: 72.602407 | E2: 72.602407 | F2: 2.1240792 | G2: 1.3223749
A3: 43840 | B3: AAPL | C3: 72.907404 | D3: 72.907404 | E3: 72.907404 | F3: 0.22609238 | G3: 1.193508
A4: 43843 | B4: AAPL | C4: 73.478864 | D4: 73.33574 | E4: 73.33574 | F4: 2.1364174 | G4: 1.2432183
A5: 43844 | B5: AAPL | C5: 74.003535 | D5: 73.554364 | E5: 73.554364 | F5: -1.3502995 | G5: 1.3752344
A6: 43845 | B6: AAPL | C6: 74.400563 | D6: 73.69699 | E6: 73.69699 | F6: -0.42856444 | G6: 1.3241002
A7: 43846 | B7: AAPL | C7: 74.980277 | D7: 73.899068 | E7: 73.899068 | F7: 1.2526123 | G7: 1.2766356
A8: 43847 | B8: AAPL | C8: 75.514922 | D8: 74.137508 | E8: 74.137508 | F8: 1.1070985 | G8: 1.2252253
A9: 43851 | B9: AAPL | C9: 75.75369 | D9: 74.299252 | E9: 74.299252 | F9: -0.67766722 | G9: 1.2206306
A10: 43852 | B10: AAPL | C10: 76.007252 | D10: 74.457328 | E10: 74.457328 | F10: 0.35696159 | G10: 1.1689261
A11: 43853 | B11: AAPL | C11: 76.08535 | D11: 74.618891 | E11: 74.618891 | F11: 0.48156163 | G11: 1.1231249
A12: 43854 | B12: AAPL | C12: 76.279046 | D12: 74.746412 | E12: 74.746412 | F12: -0.28817346 | G12: 1.0985786
A13: 43857 | B13: AAPL | C13: 76.196817 | D13: 74.72633 | E13: 74.72633 | F13: -2.9405512 | G13: 1.3495096
... A5027: 45656 | B5027: TSLA | C5027: 436.18715 | D5027: 390.86367 | E5027: 293.00478 | F5027: -3.3012093 | G5027: 3.7692231

Sheet ChartData
A1: Date | B1: AAPL | C1: MSFT | D1: SAP | E1: TSLA
A2: =RawData!A2 -> 43832 | B2: =RawData!E2 -> 72.33387 | C2: =RawData!E2516 -> 152.15843 | D2: =RawData!E3773 -> 108.9145 | E2: =RawData!E1259 -> 28.684
A3: =RawData!A3 -> 43833 | B3: =RawData!E3 -> 71.630661 | C3: =RawData!E2517 -> 150.26373 | D3: =RawData!E3774 -> 107.53967 | E3: =RawData!E1260 -> 29.534
A4: =RawData!A4 -> 43836 | B4: =RawData!E4 -> 72.201431 | C4: =RawData!E2518 -> 150.65215 | D4: =RawData!E3775 -> 106.73621 | E4: =RawData!E1261 -> 30.102667
A5: =RawData!A5 -> 43837 | B5: =RawData!E5 -> 71.861847 | C5: =RawData!E2519 -> 149.27855 | D5: =RawData!E3776 -> 107.21828 | E5: =RawData!E1262 -> 31.270666
A6: =RawData!A6 -> 43838 | B6: =RawData!E6 -> 73.017838 | C6: =RawData!E2520 -> 151.6563 | D6: =RawData!E3777 -> 107.86106 | E6: =RawData!E1263 -> 32.809334
A7: =RawData!A7 -> 43839 | B7: =RawData!E7 -> 74.568794 | C7: =RawData!E2521 -> 153.55098 | D7: =RawData!E3778 -> 109.95008 | E7: =RawData!E1264 -> 32.089333
A8: =RawData!A8 -> 43840 | B8: =RawData!E8 -> 74.737389 | C8: =RawData!E2522 -> 152.84048 | D8: =RawData!E3779 -> 110.48572 | E8: =RawData!E1265 -> 31.876667
A9: =RawData!A9 -> 43843 | B9: =RawData!E9 -> 76.334091 | C9: =RawData!E2523 -> 154.67824 | D9: =RawData!E3780 -> 110.48572 | E9: =RawData!E1266 -> 34.990665
A10: =RawData!A10 -> 43844 | B10: =RawData!E10 -> 75.303352 | C10: =RawData!E2524 -> 153.58887 | D10: =RawData!E3781 -> 110.34288 | E10: =RawData!E1267 -> 35.861332
A11: =RawData!A11 -> 43845 | B11: =RawData!E11 -> 74.980629 | C11: =RawData!E2525 -> 154.58354 | D11: =RawData!E3782 -> 109.80724 | E11: =RawData!E1268 -> 34.566666
A12: =RawData!A12 -> 43846 | B12: =RawData!E12 -> 75.919846 | C12: =RawData!E2526 -> 157.41606 | D12: =RawData!E3783 -> 109.3073 | E12: =RawData!E1269 -> 34.232666
A13: =RawData!A13 -> 43847 | B13: =RawData!E13 -> 76.760353 | C13: =RawData!E2527 -> 158.29704 | D13: =RawData!E3784 -> 112.44975 | E13: =RawData!E1270 -> 34.033333
... A1258: =RawData!A1258 -> 45656 | B1258: =RawData!E1258 -> 250.59891 | C1258: =RawData!E3772 -> 420.7587 | D1258: =RawData!E5029 -> 219.16573 | E1258: =RawData!E2515 -> 417.41

Sheet _pivot
A1: Average of close | B1: ticker
A2: date | B2: AAPL | C2: MSFT | D2: SAP.DE | E2: TSLA
A3: 43832 | B3: 72.33387 | C3: 152.15843 | D3: 108.9145 | E3: 28.684
A4: 43833 | B4: 71.630661 | C4: 150.26373 | D4: 107.53967 | E4: 29.534
A5: 43836 | B5: 72.201431 | C5: 150.65215 | D5: 106.73621 | E5: 30.102667
A6: 43837 | B6: 71.861847 | C6: 149.27855 | D6: 107.21828 | E6: 31.270666
A7: 43838 | B7: 73.017838 | C7: 151.6563 | D7: 107.86106 | E7: 32.809334
A8: 43839 | B8: 74.568794 | C8: 153.55098 | D8: 109.95008 | E8: 32.089333
A9: 43840 | B9: 74.737389 | C9: 152.84048 | D9: 110.48572 | E9: 31.876667
A10: 43843 | B10: 76.334091 | C10: 154.67824 | D10: 110.48572 | E10: 34.990665
A11: 43844 | B11: 75.303352 | C11: 153.58887 | D11: 110.34288 | E11: 35.861332
A12: 43845 | B12: 74.980629 | C12: 154.58354 | D12: 109.80724 | E12: 34.566666
A13: 43846 | B13: 75.919846 | C13: 157.41606 | D13: 109.3073 | E13: 34.232666
A14: 43847 | B14: 76.760353 | C14: 158.29704 | D14: 112.44975 | E14: 34.033333
A15: 43850 | D15: 112.18194
A16: 43851 | B16: 76.240173 | C16: 157.72864 | D16: 112.664 | E16: 36.48
A17: 43852 | B17: 76.512321 | C17: 156.97078 | D17: 113.0211 | E17: 37.970669
A18: 43853 | B18: 76.880775 | C18: 157.93704 | D18: 110.55714 | E18: 38.146667
A19: 43854 | B19: 76.659225 | C19: 156.34552 | D19: 113.28893 | E19: 37.654667
A20: 43857 | B20: 74.405022 | C20: 153.73094 | D20: 109.32515 | E20: 37.201332
A21: 43858 | B21: 76.50988 | C21: 156.74341 | D21: 106.98616 | E21: 37.793331
A22: 43859 | B22: 78.111435 | C22: 159.18747 | D22: 107.12901 | E22: 38.732666
A23: 43860 | B23: 77.998253 | C23: 163.67778 | D23: 105.50421 | E23: 42.720669
A24: 43861 | B24: 74.539886 | C24: 161.26213 | D24: 105.18284 | E24: 43.371334
A25: 43864 | B25: 74.33519 | C25: 165.1935 | D25: 107.12901 | E25: 52
A26: 43865 | B26: 76.789268 | C26: 170.63113 | D26: 109.78938 | E26: 59.137333
A27: 43866 | B27: 77.415451 | C27: 170.4227 | D27: 111.23562 | E27: 48.98
... A34: 43875 | B34: 78.444077 | C34: 175.58562 | D34: 113.5032 | E34: 53.335335
A35: 43878 | D35: 113.7353
A36: 43879 | B36: 77.007706 | C36: 177.36656 | D36: 113.66389 | E36: 57.226665
A37: 43880 | B37: 78.123001 | C37: 177.89848 | D37: 115.55651 | E37: 61.161331
A38: 43881 | B38: 77.321548 | C38: 175.18178 | D38: 114.09241 | E38: 59.960667
A39: 43882 | B39: 75.571358 | C39: 169.64384 | D39: 112.6283 | E39: 60.066666
A40: 43885 | B40: 71.981697 | C40: 162.32951 | D40: 108.23602 | E40: 55.585999
A41: 43886 | B41: 69.543526 | C41: 159.65082 | D41: 106.48624 | E41: 53.327332
A42: 43887 | B42: 70.646721 | C42: 161.6456 | D42: 106.02201 | E42: 51.919998
A43: 43888 | B43: 66.028679 | C43: 150.25623 | D43: 103.14738 | E43: 45.266666
A44: 43889 | B44: 65.990067 | C44: 153.89439 | D44: 99.594276 | E44: 44.532665
A45: 43892 | B45: 72.133774 | C45: 164.13435 | D45: 99.09433 | E45: 49.574669
A46: 43893 | B46: 69.842865 | C46: 156.26917 | D46: 100.82626 | E46: 49.700668
...
